2025-04-17 09:48:21 INFO Saving logs to /home/dasoumao/LLMBox/logs/gpt-4o-latest-mt_bench-0shot-2025_04_17-09_48_21.log
2025-04-17 09:48:21 INFO LLMBox revision: Not a git repository
2025-04-17 09:48:21 INFO Run commands (pid=17141):  /home/dasoumao/miniconda3/envs/nlp/bin/python inference.py -m gpt-4o-latest -d mt_bench --openai_api_key 'sk-Cdaw6***************************************bOYt' --model_backend openai --hf_mirror --batch_size 1
2025-04-17 09:48:21 INFO EvaluationArguments(seed=2023, logging_dir='logs', log_level='info', evaluation_results_dir='evaluation_results', log_results=True, dataset_threading=True, dataloader_workers=0)
2025-04-17 09:48:24 INFO Loading OpenAI API model `gpt-4o-latest`.
2025-04-17 09:48:24 INFO Trying to load OpenAI model with OPENAI_BASE_URL='https://nekoapi.com/v1'
2025-04-17 09:48:27 INFO Failed when trying to get_dataset_config_names(/home/dasoumao/.cache/huggingface/datasets/datasets--HuggingFaceH4--mt_bench_prompts/mt_bench_prompts.py): Couldn't find a dataset script at /home/dasoumao/.cache/huggingface/datasets/datasets--HuggingFaceH4--mt_bench_prompts/mt_bench_prompts.py
2025-04-17 09:48:27 INFO Failed when trying to get_dataset_config_names(/home/dasoumao/.cache/huggingface/datasets/datasets--HuggingFaceH4--mt_bench_prompts): Couldn't find a dataset script at /home/dasoumao/.cache/huggingface/datasets/datasets--HuggingFaceH4--mt_bench_prompts/datasets--HuggingFaceH4--mt_bench_prompts.py or any data file in the same directory.
2025-04-17 09:48:31 ERROR [load_datasets] KeyboardInterrupt: 

Traceback (most recent call last):
  File "/home/dasoumao/miniconda3/envs/nlp/lib/python3.10/site-packages/huggingface_hub/utils/_http.py", line 409, in hf_raise_for_status
    response.raise_for_status()
  File "/home/dasoumao/miniconda3/envs/nlp/lib/python3.10/site-packages/requests/models.py", line 1024, in raise_for_status
    raise HTTPError(http_error_msg, response=self)
requests.exceptions.HTTPError: 404 Client Error: Not Found for url: https://hf-mirror.com/datasets/HuggingFaceH4/mt_bench_prompts/resolve/e3a795c5e9a82ee40611c416b8a7786c73198991/mt_bench_prompts.py

The above exception was the direct cause of the following exception:

Traceback (most recent call last):
  File "/home/dasoumao/miniconda3/envs/nlp/lib/python3.10/site-packages/datasets/load.py", line 1580, in dataset_module_factory
    dataset_script_path = api.hf_hub_download(
  File "/home/dasoumao/miniconda3/envs/nlp/lib/python3.10/site-packages/huggingface_hub/utils/_validators.py", line 114, in _inner_fn
    return fn(*args, **kwargs)
  File "/home/dasoumao/miniconda3/envs/nlp/lib/python3.10/site-packages/huggingface_hub/hf_api.py", line 5475, in hf_hub_download
    return hf_hub_download(
  File "/home/dasoumao/miniconda3/envs/nlp/lib/python3.10/site-packages/huggingface_hub/utils/_validators.py", line 114, in _inner_fn
    return fn(*args, **kwargs)
  File "/home/dasoumao/miniconda3/envs/nlp/lib/python3.10/site-packages/huggingface_hub/file_download.py", line 961, in hf_hub_download
    return _hf_hub_download_to_cache_dir(
  File "/home/dasoumao/miniconda3/envs/nlp/lib/python3.10/site-packages/huggingface_hub/file_download.py", line 1024, in _hf_hub_download_to_cache_dir
    (url_to_download, etag, commit_hash, expected_size, xet_file_data, head_call_error) = _get_metadata_or_catch_error(
  File "/home/dasoumao/miniconda3/envs/nlp/lib/python3.10/site-packages/huggingface_hub/file_download.py", line 1484, in _get_metadata_or_catch_error
    metadata = get_hf_file_metadata(
  File "/home/dasoumao/miniconda3/envs/nlp/lib/python3.10/site-packages/huggingface_hub/utils/_validators.py", line 114, in _inner_fn
    return fn(*args, **kwargs)
  File "/home/dasoumao/miniconda3/envs/nlp/lib/python3.10/site-packages/huggingface_hub/file_download.py", line 1401, in get_hf_file_metadata
    r = _request_wrapper(
  File "/home/dasoumao/miniconda3/envs/nlp/lib/python3.10/site-packages/huggingface_hub/file_download.py", line 285, in _request_wrapper
    response = _request_wrapper(
  File "/home/dasoumao/miniconda3/envs/nlp/lib/python3.10/site-packages/huggingface_hub/file_download.py", line 309, in _request_wrapper
    hf_raise_for_status(response)
  File "/home/dasoumao/miniconda3/envs/nlp/lib/python3.10/site-packages/huggingface_hub/utils/_http.py", line 420, in hf_raise_for_status
    raise _format(EntryNotFoundError, message, response) from e
huggingface_hub.errors.EntryNotFoundError: 404 Client Error. (Request ID: Root=1-68005deb-68fc494b61723b6d27645237;56894f3b-2bc7-433d-9159-5b72d11d390b)

Entry Not Found for url: https://hf-mirror.com/datasets/HuggingFaceH4/mt_bench_prompts/resolve/e3a795c5e9a82ee40611c416b8a7786c73198991/mt_bench_prompts.py.

During handling of the above exception, another exception occurred:

Traceback (most recent call last):
  File "/home/dasoumao/LLMBox/utilization/utils/catch_error.py", line 40, in wrapper
    return func(*args, **kwargs)
  File "/home/dasoumao/LLMBox/utilization/load_dataset.py", line 384, in load_datasets
    datasets.extend(
  File "/home/dasoumao/LLMBox/utilization/load_dataset.py", line 271, in load_dataset
    available_subsets_by_cls = get_subsets(dataset_name, dataset_classes, args, cache_paths)
  File "/home/dasoumao/LLMBox/utilization/load_dataset.py", line 121, in get_subsets
    s = get_dataset_config_names(path=path, download_config=download_config, trust_remote_code=True)
  File "/home/dasoumao/miniconda3/envs/nlp/lib/python3.10/site-packages/datasets/inspect.py", line 165, in get_dataset_config_names
    dataset_module = dataset_module_factory(
  File "/home/dasoumao/miniconda3/envs/nlp/lib/python3.10/site-packages/datasets/load.py", line 1629, in dataset_module_factory
    ).get_module()
  File "/home/dasoumao/miniconda3/envs/nlp/lib/python3.10/site-packages/datasets/load.py", line 1019, in get_module
    data_files = DataFilesDict.from_patterns(
  File "/home/dasoumao/miniconda3/envs/nlp/lib/python3.10/site-packages/datasets/data_files.py", line 690, in from_patterns
    else DataFilesList.from_patterns(
  File "/home/dasoumao/miniconda3/envs/nlp/lib/python3.10/site-packages/datasets/data_files.py", line 583, in from_patterns
    resolve_pattern(
  File "/home/dasoumao/miniconda3/envs/nlp/lib/python3.10/site-packages/datasets/data_files.py", line 361, in resolve_pattern
    for filepath, info in fs.glob(pattern, detail=True, **glob_kwargs).items()
  File "/home/dasoumao/miniconda3/envs/nlp/lib/python3.10/site-packages/huggingface_hub/hf_file_system.py", line 521, in glob
    return super().glob(path, **kwargs)
  File "/home/dasoumao/miniconda3/envs/nlp/lib/python3.10/site-packages/fsspec/spec.py", line 609, in glob
    allpaths = self.find(root, maxdepth=depth, withdirs=True, detail=True, **kwargs)
  File "/home/dasoumao/miniconda3/envs/nlp/lib/python3.10/site-packages/huggingface_hub/hf_file_system.py", line 556, in find
    return super().find(
  File "/home/dasoumao/miniconda3/envs/nlp/lib/python3.10/site-packages/fsspec/spec.py", line 500, in find
    out[path] = self.info(path)
  File "/home/dasoumao/miniconda3/envs/nlp/lib/python3.10/site-packages/huggingface_hub/hf_file_system.py", line 719, in info
    paths_info = self._api.get_paths_info(
  File "/home/dasoumao/miniconda3/envs/nlp/lib/python3.10/site-packages/huggingface_hub/utils/_validators.py", line 114, in _inner_fn
    return fn(*args, **kwargs)
  File "/home/dasoumao/miniconda3/envs/nlp/lib/python3.10/site-packages/huggingface_hub/hf_api.py", line 3354, in get_paths_info
    response = get_session().post(
  File "/home/dasoumao/miniconda3/envs/nlp/lib/python3.10/site-packages/requests/sessions.py", line 637, in post
    return self.request("POST", url, data=data, json=json, **kwargs)
  File "/home/dasoumao/miniconda3/envs/nlp/lib/python3.10/site-packages/requests/sessions.py", line 589, in request
    resp = self.send(prep, **send_kwargs)
  File "/home/dasoumao/miniconda3/envs/nlp/lib/python3.10/site-packages/requests/sessions.py", line 703, in send
    r = adapter.send(request, **kwargs)
  File "/home/dasoumao/miniconda3/envs/nlp/lib/python3.10/site-packages/huggingface_hub/utils/_http.py", line 96, in send
    return super().send(request, *args, **kwargs)
  File "/home/dasoumao/miniconda3/envs/nlp/lib/python3.10/site-packages/requests/adapters.py", line 667, in send
    resp = conn.urlopen(
  File "/home/dasoumao/miniconda3/envs/nlp/lib/python3.10/site-packages/urllib3/connectionpool.py", line 787, in urlopen
    response = self._make_request(
  File "/home/dasoumao/miniconda3/envs/nlp/lib/python3.10/site-packages/urllib3/connectionpool.py", line 534, in _make_request
    response = conn.getresponse()
  File "/home/dasoumao/miniconda3/envs/nlp/lib/python3.10/site-packages/urllib3/connection.py", line 516, in getresponse
    httplib_response = super().getresponse()
  File "/home/dasoumao/miniconda3/envs/nlp/lib/python3.10/http/client.py", line 1375, in getresponse
    response.begin()
  File "/home/dasoumao/miniconda3/envs/nlp/lib/python3.10/http/client.py", line 318, in begin
    version, status, reason = self._read_status()
  File "/home/dasoumao/miniconda3/envs/nlp/lib/python3.10/http/client.py", line 279, in _read_status
    line = str(self.fp.readline(_MAXLINE + 1), "iso-8859-1")
  File "/home/dasoumao/miniconda3/envs/nlp/lib/python3.10/socket.py", line 717, in readinto
    return self._sock.recv_into(b)
  File "/home/dasoumao/miniconda3/envs/nlp/lib/python3.10/ssl.py", line 1307, in recv_into
    return self.read(nbytes, buffer)
  File "/home/dasoumao/miniconda3/envs/nlp/lib/python3.10/ssl.py", line 1163, in read
    return self._sslobj.read(len, buffer)
KeyboardInterrupt

